<?xml version="1.0"?>
<robot name="left_cam">
    <link name="base_link">
        <visual>
            <geometry>
                <box size="0.05 0.04 0.005" />
            </geometry>
            <material name="grey">
                <color  rgba="0.7 0.7 0.7 1" />
            </material>
        </visual>
        <collision>
            <geometry>
                <box size="0.05 0.04 0.005" />
            </geometry>
        </collision>
    </link>

<!-- .............................HALTERUNG 1................................-->
    <link name="halterung_1">
        <visual>
            <geometry>
                <box size="0.015 0.006 0.045" />
            </geometry>
            <material name="grey">
                <color  rgba="0.7 0.7 0.7 1" />
            </material>
        </visual>
        <collision>
            <geometry>
                <box size="0.015 0.006 0.045" />
            </geometry>
        </collision>
    </link>

    <joint name="base_link_to_halterung_1" type="fixed">
        <parent link="base_link" />
        <child link="halterung_1" />
        <origin xyz="0.014 0.017 0.025" />
    </joint>

<!-- ..............................HALTERUNG 2...............................-->
    <link name="halterung_2">
        <visual>
            <geometry>
                <box size="0.015 0.006 0.045" />
            </geometry>
            <material name="grey">
                <color  rgba="0.7 0.7 0.7 1" />
            </material>
        </visual>
        <collision>
            <geometry>
                <box size="0.015 0.006 0.045" />
            </geometry>
        </collision>
    </link>

    <joint name="base_link_to_halterung_2" type="fixed">
        <parent link="base_link" />
        <child link="halterung_2" />
        <origin xyz="0.014 -0.017 0.025" />
    </joint>

<!-- .............................SERVO 1................................-->
    <link name="servo_1">
        <visual>
            <geometry>
                <box size="0.03 0.028 0.013" />
            </geometry>
            <material name="blue">
                <color  rgba="0.118 0.565 1 1" />
            </material>
        </visual>
        <collision>
            <geometry>
                <box size="0.03 0.028 0.013" />
            </geometry>
        </collision>
    </link>

    <joint name="halterung_1_to_servo_1" type="fixed">
        <parent link="halterung_1" />
        <child link="servo_1" />
        <origin xyz="-0.005 -0.017 0.016" />
    </joint>

<!-- .............................WING 1................................-->

    <link name="wing_1">
        <visual>
            <geometry>
                <box size="0.005 0.028 0.007" />
            </geometry>
            <material name="grey" />
            <origin xyz="0 -0.0105 0" />
        </visual>
        <collision>
            <geometry>
                <box size="0.005 0.028 0.007" />
            </geometry>
        </collision>
    </link>

    <joint name="servo_1_to_wing_1" type="continuous">
        <parent link="servo_1" />
        <child link="wing_1" />
        <origin xyz="-0.0175 0.0105 0" />
    </joint>

<!-- .............................SERVO 2................................-->

    <link name="servo_2">
        <visual>
            <geometry>
                <box size="0.024 0.04 0.031" />
            </geometry>
            <material name="blue">
                <color  rgba="0.118 0.565 1 1" />
            </material>
        </visual>
        <collision>
            <geometry>
                <box size="0.028 0.04 0.031" />
            </geometry>
        </collision>
    </link>

    <joint name="wing_1_to_servo_2" type="fixed">
        <parent link="wing_1" />
        <child link="servo_2" />
        <origin xyz="-0.014 -0.0105 -0.007" />
    </joint>

<!-- .............................WING 2................................-->

    <link name="wing_2">
        <visual>
            <geometry>
                <box size="0.018 0.007 0.005" />
            </geometry>
             <material name="grey" />
            <origin xyz="0.005 0 0" />
        </visual>
        <collision>
            <geometry>
                <box size="0.018 0.007 0.005" />
            </geometry>
        </collision>
    </link>

    <joint name="servo_2_to_wing_2" type="continuous">
        <parent link="servo_2" />
        <child link="wing_2" />
        <origin xyz="0 0.01 0.018" />
        <axis xyz="0 0 1" />
    </joint>

<!-- .............................CAM 1................................-->

    <link name="cam_1">
        <visual>
            <geometry>
                <sphere radius="0.03"/>
            </geometry>
             <material name="grey" />
            <origin xyz="0 0 0" />
        </visual>
        <collision>
            <geometry>
                <sphere radius="0.03"/>
            </geometry>
        </collision>
    </link>

    <joint name="wing_2_to_cam_1" type="fixed">
        <parent link="wing_2" />
        <child link="cam_1" />
        <origin xyz="0 0 0.0325" />
    </joint>

<!-- .............................LED RING 1................................-->

    <link name="led_1">
        <visual>
            <geometry>
                <cylinder radius="0.022" length="0.01"/>
            </geometry>
             <material name="grey" />
            <origin xyz="0 0 0" rpy="1.570796323 0 0"/>
        </visual>
        <collision>
            <geometry>
                <cylinder radius="0.022" length="0.01"/>
            </geometry>
        </collision>
    </link>

    <joint name="cam_1_to_led_1" type="fixed">
        <parent link="cam_1" />
        <child link="led_1" />
        <origin xyz="0 0.03 0" />
    </joint>
</robot>
